<?xml version="1.0" ?>
<!-- =================================================================================== -->
<!-- |    This document was autogenerated by xacro from /home/mluser/catkin_ws/src/tracker_api/taurob_robots_description_tracker/sieglinde_new/urdf/tracker/tracker.urdf.xacro | -->
<!-- |    EDITING THIS FILE BY HAND IS NOT RECOMMENDED                                 | -->
<!-- =================================================================================== -->
<!-- 
  * Meta xacro for the tracker robot (t3, eg Karl) 
  * This file contains the complete robots description with arm. 
  * 
  *  This model assembles a tracker with:
  *      - tracker chassis 
  *      - arm (old)
  *      - has a lidar 
  *      
  *  Includetree: 
  *  chassis.urdf.xacro 
  *      ==> $(find hector_xacro_tools)/urdf/inertia_tensors.urdf.xacro
  *      ==> $(find taurob_robots_description)/urdf/chassis.gazebo.xacro
  *      ==> $(find taurob_robots_description)/urdf/taurob_camera.xacro
  *      ==> $(find taurob_robots_description)/urdf/taurob_camera.gazebo
  *      ==> $(find velodyne_description)/urdf/VLP-16.urdf.xacro
  *      
  *  arm_collision_geoms_simple.urdf.xacro
  *  
  *  arm_macros.urdf.xacro
  *      ==> $(find hector_xacro_tools)/urdf/inertia_tensors.urdf.xacro
  *      ==> $(find taurob_robots_description)/urdf/taurob_camera.xacro
  *      ==> $(find taurob_robots_description)/urdf/taurob_camera.gazebo
  *
  * Copyright (c) 2017 taurob GmbH. All rights reserved. Confidential and proprietary.
  * Perfektastrasse 57/7, 1230 Wien, Austria. office@taurob.com     
-->
<robot name="taurob_tracker">
    <!---<joint name="dummyjoint" type="fixed">
    <origin
        xyz="0 0 0"
        rpy="-1.5708 0 3.141" />
    <parent
        link="arm_flange_link" />
    <child
        link="base_arm" />
</joint>-->
    <link name="base_arm">
        <inertial>
            <origin rpy="0 0 0" xyz="7.983E-19 -5.2611E-34 0.019067" />
            <mass value="2" />
            <!-- <inertia
        ixx="9.6981E-05"
        ixy="-1.903E-36"
        ixz="1.5021E-21"
        iyy="9.6981E-05"
        iyz="-1.0565E-36"
        izz="0.00011306" /> -->
            <inertia ixx="0.002" ixy="0.0" ixz="0.0" iyy="0.02" iyz="0.0" izz="0.002" />
        </inertial>
        <visual>
            <origin rpy="0 0 0" xyz="0 0 0" />
            <geometry>
                <mesh filename="package://sieglinde_new/meshes/arm/base_link.STL" />
            </geometry>
            <material name="">
                <color rgba="0.79216 0.81961 0.93333 1" />
            </material>
        </visual>
        <collision>
            <origin rpy="0 0 0" xyz="0 0 0" />
            <geometry>
                <mesh filename="package://sieglinde_new/meshes/arm/base_link.STL" />
            </geometry>
        </collision>
    </link>
    <link name="arm_link_1">
        <inertial>
            <origin rpy="0 0 0" xyz="0.0038798 7.2516E-08 0.056206" />
            <mass value="2" />
            <!-- <inertia
        ixx="0.00091868"
        ixy="-1.844E-11"
        ixz="-8.2868E-05"
        iyy="0.0007717"
        iyz="7.2531E-11"
        izz="0.00069796" /> -->
            <inertia ixx="0.002" ixy="0.0" ixz="0.0" iyy="0.02" iyz="0.0" izz="0.002" />
        </inertial>
        <visual>
            <origin rpy="0 0 0" xyz="0 0 0" />
            <geometry>
                <mesh filename="package://sieglinde_new/meshes/arm/Link1.STL" />
            </geometry>
            <material name="">
                <color rgba="0.79216 0.81961 0.93333 1" />
            </material>
        </visual>
        <collision>
            <origin rpy="0 0 0" xyz="0 0 0" />
            <geometry>
                <mesh filename="package://sieglinde_new/meshes/arm/Link1.STL" />
            </geometry>
        </collision>
    </link>
    <!-- changed 22.05.23 from Taurob: rpy="1.5708 1.5708 0" -->
    <joint name="arm_joint_1" type="revolute">
        <origin rpy="1.5708 1.5708 0" xyz="0 -0.039 0" />
        <parent link="base_arm" />
        <child link="arm_link_1" />
        <axis xyz="0 0 1" />
        <!-- <limit
      lower="-3.141"
      upper="3.141"
      effort="10"
      velocity="3.141" /> -->
        <!--limit 
      lower="${0 * M_PI / 180}" 
      upper="${330 * M_PI / 180}" 
      effort="1000" 
      velocity="${80.2141 * M_PI / 180}"/-->
        <limit effort="1000" lower="0.00" upper="3.123" velocity="1.4000001515239835" />
        <dynamics damping="0.5" friction="0.0" />
    </joint>
    <link name="arm_link_2">
        <inertial>
            <origin rpy="0 0 0" xyz="0.027796 -0.27705 -0.076051" />
            <mass value="7" />
            <!-- <inertia
        ixx="0.27927"
        ixy="-1.0333E-05"
        ixz="-9.7702E-06"
        iyy="0.012963"
        iyz="-8.4319E-05"
        izz="0.28228" /> -->
            <inertia ixx="0.002" ixy="0.0" ixz="0.0" iyy="0.02" iyz="0.0" izz="0.002" />
        </inertial>
        <visual>
            <origin rpy="0 0 0" xyz="0 0 0" />
            <geometry>
                <mesh filename="package://sieglinde_new/meshes/arm/Link2.STL" />
            </geometry>
            <material name="">
                <color rgba="0.79216 0.81961 0.93333 1" />
            </material>
        </visual>
        <collision>
            <origin rpy="0 0 0" xyz="0 0 0" />
            <geometry>
                <mesh filename="package://sieglinde_new/meshes/arm/Link2.STL" />
            </geometry>
        </collision>
    </link>
    <!-- changed 22.05.23 from Taurob: rpy="-1.5708 0 1.5708" -->
    <joint name="arm_joint_2" type="revolute">
        <origin rpy="-1.5708 6.2831 1.5708" xyz="0.03 0 0.0725" />
        <parent link="arm_link_1" />
        <child link="arm_link_2" />
        <axis xyz="0 0 -1" />
        <!-- <limit
      lower="-1.5708"
      upper="1.5708"
      effort="10"
      velocity="3.141" /> -->
        <!--limit 
      lower="${0* M_PI / 180}" 
      upper="${180 * M_PI / 180}" 
      effort="1000" 
      velocity="${31.5126 * M_PI / 180}"/-->
        <limit effort="1000" lower="0.00" upper="1.19" velocity="0.5499986258639651" />
        <dynamics damping="0.5" friction="0.0" />
    </joint>
    <link name="arm_link_3">
        <inertial>
            <origin rpy="0 0 0" xyz="0.025884 -0.0001487 0.21827" />
            <mass value="3.5" />
            <!-- <inertia
        ixx="0.078643"
        ixy="5.6989E-06"
        ixz="6.0713E-05"
        iyy="0.07821"
        iyz="0.00011129"
        izz="0.0038311" /> -->
            <inertia ixx="0.002" ixy="0.0" ixz="0.0" iyy="0.02" iyz="0.0" izz="0.002" />
        </inertial>
        <visual>
            <origin rpy="0 0 0" xyz="0 0 0" />
            <geometry>
                <mesh filename="package://sieglinde_new/meshes/arm/Link3.STL" />
            </geometry>
            <material name="">
                <color rgba="0.79216 0.81961 0.93333 1" />
            </material>
        </visual>
        <collision>
            <origin rpy="0 0 0" xyz="0 0 0" />
            <geometry>
                <mesh filename="package://sieglinde_new/meshes/arm/Link3.STL" />
            </geometry>
        </collision>
    </link>
    <!-- changed 22.05.23 from Taurob: rpy="1.5708 -1.5708 0" -->
    <joint name="arm_joint_3" type="revolute">
        <origin rpy="1.5708 -1.5708 3.5341500000000003" xyz="0 -0.5545 0" />
        <parent link="arm_link_2" />
        <child link="arm_link_3" />
        <axis xyz="1 0 0" />
        <!-- <limit
      lower="-3.141"
      upper="3.141"
      effort="10"
      velocity="3.141" /> -->
        <!--limit 
      lower="${0 * M_PI / 180}" 
      upper="${323* M_PI / 180}" 
      effort="1000" 
      velocity="${57.2958 * M_PI / 180}"/-->
        <limit effort="1000" lower="0.00" upper="5.651" velocity="1.0000003575641672" />
        <dynamics damping="0.5" friction="0.0" />
    </joint>
    <!-- [BEGIN] ===  Arm transmission section. Needed for ros_control. ===-->
    <transmission name="arm_joint_1_joint_transmssion">
        <type>transmission_interface/SimpleTransmission</type>
        <joint name="arm_joint_1">
            <hardwareInterface>hardware_interface/PositionJointInterface</hardwareInterface>
        </joint>
        <actuator name="arm_joint_1_motor">
            <hardwareInterface>hardware_interface/PositionJointInterface</hardwareInterface>
            <mechanicalReduction>1</mechanicalReduction>
        </actuator>
    </transmission>
    <transmission name="arm_joint_2_joint_transmssion">
        <type>transmission_interface/SimpleTransmission</type>
        <joint name="arm_joint_2">
            <hardwareInterface>hardware_interface/PositionJointInterface</hardwareInterface>
        </joint>
        <actuator name="arm_joint_2_motor">
            <hardwareInterface>hardware_interface/PositionJointInterface</hardwareInterface>
            <mechanicalReduction>1</mechanicalReduction>
        </actuator>
    </transmission>
    <transmission name="arm_joint_3_joint_transmssion">
        <type>transmission_interface/SimpleTransmission</type>
        <joint name="arm_joint_3">
            <hardwareInterface>hardware_interface/PositionJointInterface</hardwareInterface>
        </joint>
        <actuator name="arm_joint_3_motor">
            <hardwareInterface>hardware_interface/PositionJointInterface</hardwareInterface>
            <mechanicalReduction>1</mechanicalReduction>
        </actuator>
    </transmission>
    <transmission name="arm_joint_4_joint_transmssion">
        <type>transmission_interface/SimpleTransmission</type>
        <joint name="arm_joint_4">
            <hardwareInterface>hardware_interface/PositionJointInterface</hardwareInterface>
        </joint>
        <actuator name="arm_joint_4_motor">
            <hardwareInterface>hardware_interface/PositionJointInterface</hardwareInterface>
            <mechanicalReduction>1</mechanicalReduction>
        </actuator>
    </transmission>
    <!-- [END] ===  Arm transmission section. Needed for ros_control. ===-->
    <!-- changed 22.05.23 from Taurob: rpy="0 -1.5708 -1.5708" -->
    <joint name="arm_joint_4" type="revolute">
        <origin rpy="0 2.356125 -1.5708" xyz="0.128 -0.0115 0.438" />
        <parent link="arm_link_3" />
        <child link="arm_link_4" />
        <axis xyz="0 1 0" />
        <!-- <limit
      lower="-3.14"
      upper="3.14"
      effort="4"
      velocity="3.14" /> -->
        <!--limit 
      lower="${0 * M_PI / 180}" 
      upper="4.74399995803833" 
      effort="1000" 
      velocity="${57.2958 * M_PI / 180}"/-->
        <limit effort="1000" lower="0.00" upper="4.428" velocity="1.0000003575641672" />
        <dynamics damping="1.0" friction="5.0" />
    </joint>
    <link name="arm_link_4">
        <inertial>
            <origin rpy="0 0 0" xyz="0.065104 -0.00028882 -0.0090979" />
            <mass value="0.64147" />
            <!-- <inertia
        ixx="0.00068231"
        ixy="-5.9473E-06"
        ixz="1.8695E-05"
        iyy="0.0016609"
        iyz="1.5591E-06"
        izz="0.0017673" /> -->
            <inertia ixx="0.002" ixy="0.0" ixz="0.0" iyy="0.02" iyz="0.0" izz="0.002" />
        </inertial>
        <visual>
            <origin rpy="0 0 0" xyz="0 0 0" />
            <geometry>
                <mesh filename="package://sieglinde_new/meshes/gripper/Link4.STL" />
            </geometry>
            <material name="">
                <color rgba="0.8 0.8 0.9 1" />
            </material>
        </visual>
        <collision>
            <origin rpy="0 0 0" xyz="0 0 0" />
            <geometry>
                <mesh filename="package://sieglinde_new/meshes/gripper/Link4.STL" />
            </geometry>
        </collision>
    </link>
    <link name="arm_link_5">
        <inertial>
            <origin rpy="0 0 0" xyz="0.0044064 -0.0001 0.096772" />
            <mass value="0.25632" />
            <!-- <inertia
        ixx="9.8592E-05"
        ixy="-2.4552E-18"
        ixz="-7.322E-07"
        iyy="0.00010734"
        iyz="7.5695E-19"
        izz="0.00017125" /> -->
            <inertia ixx="0.002" ixy="0.0" ixz="0.0" iyy="0.02" iyz="0.0" izz="0.002" />
        </inertial>
        <visual>
            <origin rpy="0 0 0" xyz="0 0 0" />
            <geometry>
                <mesh filename="package://sieglinde_new/meshes/gripper/Link5.STL" />
            </geometry>
            <material name="">
                <color rgba="0.8 0.8 0.9 1" />
            </material>
        </visual>
        <collision>
            <origin rpy="0 0 0" xyz="0 0 0" />
            <geometry>
                <mesh filename="package://sieglinde_new/meshes/gripper/Link5.STL" />
            </geometry>
        </collision>
    </link>
    <joint name="arm_joint_5" type="continuous">
        <origin rpy="0 1.5708 0" xyz="0.087 0 -0.0015" />
        <parent link="arm_link_4" />
        <child link="arm_link_5" />
        <axis xyz="0 0 1" />
        <limit effort="10" velocity="3.14" />
        <dynamics damping="1.0" friction="5.0" />
    </joint>
    <link name="Gripper">
        <inertial>
            <origin rpy="0 0 0" xyz="-0.008388 -0.014564 0.024958" />
            <mass value="0.014249" />
            <!-- <inertia
        ixx="1.511E-06"
        ixy="-3.802E-07"
        ixz="6.8871E-09"
        iyy="1.07E-06"
        iyz="1.5611E-08"
        izz="1.5649E-06" /> -->
            <inertia ixx="0.002" ixy="0.0" ixz="0.0" iyy="0.02" iyz="0.0" izz="0.002" />
        </inertial>
        <visual>
            <origin rpy="0 0 0" xyz="0 0 0" />
            <geometry>
                <mesh filename="package://sieglinde_new/meshes/gripper/Gripper1.STL" />
            </geometry>
            <material name="">
                <color rgba="0.8 0.8 0.9 1" />
            </material>
        </visual>
        <collision>
            <origin rpy="0 0 0" xyz="0 0 0" />
            <geometry>
                <mesh filename="package://sieglinde_new/meshes/gripper/Gripper1.STL" />
            </geometry>
        </collision>
    </link>
    <joint name="Grip" type="revolute">
        <origin rpy="0 0 3.1416" xyz="0.02025 0.034974 0.137" />
        <parent link="arm_link_5" />
        <child link="Gripper" />
        <axis xyz="0 0 1" />
        <limit effort="4" lower="-3.14" upper="3.14" velocity="3.14" />
        <dynamics damping="1.0" friction="5.0" />
    </joint>
    <link name="Gripper2">
        <inertial>
            <origin rpy="0 0 0" xyz="-0.0084188 0.014546 0.024958" />
            <mass value="0.014249" />
            <!-- <inertia
        ixx="1.5095E-06"
        ixy="3.8104E-07"
        ixz="1.0076E-08"
        iyy="1.0715E-06"
        iyz="-1.377E-08"
        izz="1.5649E-06" /> -->
            <inertia ixx="0.002" ixy="0.0" ixz="0.0" iyy="0.02" iyz="0.0" izz="0.002" />
        </inertial>
        <visual>
            <origin rpy="0 0 0" xyz="0 0 0" />
            <geometry>
                <mesh filename="package://sieglinde_new/meshes/gripper/Gripper2.STL" />
            </geometry>
            <material name="">
                <color rgba="0.8 0.8 0.9 1" />
            </material>
        </visual>
        <collision>
            <origin rpy="0 0 0" xyz="0 0 0" />
            <geometry>
                <mesh filename="package://sieglinde_new/meshes/gripper/Gripper2.STL" />
            </geometry>
        </collision>
    </link>
    <joint name="g2" type="revolute">
        <origin rpy="0 0 3.1416" xyz="0.02025 -0.035174 0.137" />
        <parent link="arm_link_5" />
        <child link="Gripper2" />
        <axis xyz="0 0 1" />
        <limit effort="4" lower="-3.14" upper="3.14" velocity="3.14" />
        <dynamics damping="0.5" friction="0.0" />
        <mimic joint="Grip" multiplier="1" offset="0" />
    </joint>
    <link name="Gripper3">
        <inertial>
            <origin rpy="0 0 0" xyz="0.016807 1.7794E-05 0.024958" />
            <mass value="0.014249" />
            <!-- <inertia
        ixx="8.5099E-07"
        ixy="-8.4555E-10"
        ixz="-1.6963E-08"
        iyy="1.73E-06"
        iyz="-1.8412E-09"
        izz="1.5649E-06" /> -->
            <inertia ixx="0.002" ixy="0.0" ixz="0.0" iyy="0.02" iyz="0.0" izz="0.002" />
        </inertial>
        <visual>
            <origin rpy="0 0 0" xyz="0 0 0" />
            <geometry>
                <mesh filename="package://sieglinde_new/meshes/gripper/Gripper3.STL" />
            </geometry>
            <material name="">
                <color rgba="0.8 0.8 0.9 1" />
            </material>
        </visual>
        <collision>
            <origin rpy="0 0 0" xyz="0 0 0" />
            <geometry>
                <mesh filename="package://sieglinde_new/meshes/gripper/Gripper3.STL" />
            </geometry>
        </collision>
    </link>
    <joint name="g3" type="revolute">
        <origin rpy="0 0 3.1416" xyz="-0.0405 -0.00010001 0.137" />
        <parent link="arm_link_5" />
        <child link="Gripper3" />
        <axis xyz="0 0 1" />
        <limit effort="4" lower="-3.14" upper="3.14" velocity="3.14" />
        <dynamics damping="0.5" friction="0.0" />
        <mimic joint="Grip" multiplier="1" offset="0" />
    </joint>
    <!-- TODO: Please use consistent joint names, keeping the current ones for now-->
    <!-- [BEGIN] ===  Gripper transmission section. Needed for ros_control. === -->
    <transmission name="arm_joint_5_joint_transmssion">
        <type>transmission_interface/SimpleTransmission</type>
        <joint name="arm_joint_5">
            <hardwareInterface>hardware_interface/PositionJointInterface</hardwareInterface>
        </joint>
        <actuator name="arm_joint_5_motor">
            <hardwareInterface>hardware_interface/PositionJointInterface</hardwareInterface>
            <mechanicalReduction>1</mechanicalReduction>
        </actuator>
    </transmission>
    <transmission name="grip_joint_transmssion">
        <type>transmission_interface/SimpleTransmission</type>
        <joint name="Grip">
            <hardwareInterface>hardware_interface/PositionJointInterface</hardwareInterface>
        </joint>
        <actuator name="grip_joint_motor">
            <hardwareInterface>hardware_interface/PositionJointInterface</hardwareInterface>
            <mechanicalReduction>1</mechanicalReduction>
        </actuator>
    </transmission>
    <transmission name="g2_joint_transmssion">
        <type>transmission_interface/SimpleTransmission</type>
        <joint name="g2">
            <hardwareInterface>hardware_interface/PositionJointInterface</hardwareInterface>
        </joint>
        <actuator name="g2_joint_motor">
            <hardwareInterface>hardware_interface/PositionJointInterface</hardwareInterface>
            <mechanicalReduction>1</mechanicalReduction>
        </actuator>
    </transmission>
    <transmission name="g3_joint_transmssion">
        <type>transmission_interface/SimpleTransmission</type>
        <joint name="g3">
            <hardwareInterface>hardware_interface/PositionJointInterface</hardwareInterface>
        </joint>
        <actuator name="g3_joint_motor">
            <hardwareInterface>hardware_interface/PositionJointInterface</hardwareInterface>
            <mechanicalReduction>1</mechanicalReduction>
        </actuator>
    </transmission>
    <!-- [END] ===  Arm transmission section. Needed for ros_control. === -->
    <joint name="dummyjointbox" type="fixed">
        <origin rpy="0 0 0" xyz="-0.57 -0.03 0.1" />
        <parent link="chassis_link" />
        <child link="boxlink" />
    </joint>
    <link name="boxlink">
        <visual>
            <origin rpy="0 0 0" xyz="0 0 0" />
            <geometry>
                <box size="0.3 0.3 0.2" />
            </geometry>
            <material name="Grey">
                <color rgba="0.8 0.8 0.8 1.0" />
            </material>
        </visual>
        <collision>
            <origin rpy="0 0 0" xyz="0 0 0" />
            <geometry>
                <box size="0.3 0.3 0.2" />
            </geometry>
        </collision>
        <inertial>
            <mass value="0.1" />
            <origin xyz="0 0 0" rpy="0 0 0" />
            <inertia ixx="0.03" iyy="0.03" izz="0.03" ixy="0.0" ixz="0.0" iyz="0.0" />
        </inertial>
    </link>
    <joint name="dummyjointkamerabox" type="fixed">
        <origin rpy="-1.5708 0 0" xyz="0.235 0 0" />
        <parent link="chassis_link" />
        <child link="kamerabox" />
    </joint>
    <link name="kamerabox">
        <inertial>
            <origin rpy="0 0 0" xyz="0.0012767 -2.747E-18 -0.049394" />
            <mass value="1" />
            <inertia ixx="0.2515" ixy="-1.4629E-17" ixz="-0.0036599" iyy="0.21384" iyz="5.192E-18" izz="0.26871" />
        </inertial>
        <visual>
            <origin rpy="0 0 0" xyz="0 0 0" />
            <geometry>
                <mesh filename="package://sieglinde_new/meshes/misc/kamerabox.STL" />
            </geometry>
            <material name="">
                <color rgba="0.79216 0.81961 0.93333 1" />
            </material>
        </visual>
        <collision>
            <origin rpy="0 0 0" xyz="0 0 0" />
            <geometry>
                <mesh filename="package://sieglinde_new/meshes/misc/kamerabox.STL" />
            </geometry>
        </collision>
    </link>
    <link name="halterung">
        <inertial>
            <origin rpy="0 0 0" xyz="-0.00051606 -0.0060421 0.02885" />
            <mass value="1" />
            <inertia ixx="3.9796E-05" ixy="3.0397E-07" ixz="-6.7777E-07" iyy="6.9462E-05" iyz="5.693E-06" izz="4.4043E-05" />
        </inertial>
        <visual>
            <origin rpy="0 0 0" xyz="0 0 0" />
            <geometry>
                <mesh filename="package://sieglinde_new/meshes/misc/halterung.STL" />
            </geometry>
            <material name="">
                <color rgba="0.49804 0.49804 0.49804 1" />
            </material>
        </visual>
        <collision>
            <origin rpy="0 0 0" xyz="0 0 0" />
            <geometry>
                <mesh filename="package://sieglinde_new/meshes/misc/halterung.STL" />
            </geometry>
        </collision>
    </link>
    <joint name="halterunglink" type="fixed">
        <origin rpy="1.5708 1.5708 0" xyz="0.065 -0.1 0" />
        <parent link="kamerabox" />
        <child link="halterung" />
        <axis xyz="0 0 0" />
    </joint>
    <link name="L515">
        <inertial>
            <origin rpy="0 0 0" xyz="2.3425E-06 -0.19271 -0.086411" />
            <mass value="1" />
            <inertia ixx="0.21876" ixy="-8.0619E-06" ixz="-3.3368E-06" iyy="0.2693" iyz="-0.0051679" izz="0.25593" />
        </inertial>
        <visual>
            <origin rpy="0 0 0" xyz="0 0 0" />
            <geometry>
                <mesh filename="package://sieglinde_new/meshes/misc/L515.STL" />
            </geometry>
            <material name="">
                <color rgba="0.79216 0.81961 0.93333 1" />
            </material>
        </visual>
        <collision>
            <origin rpy="0 0 0" xyz="0 0 0" />
            <geometry>
                <mesh filename="package://sieglinde_new/meshes/misc/L515.STL" />
            </geometry>
        </collision>
    </link>
    <joint name="L515link" type="fixed">
        <origin rpy="1.5708 0 3.1416" xyz="0 0.0231 0.0445" />
        <parent link="halterung" />
        <child link="L515" />
        <axis xyz="0 0 0" />
    </joint>
    <!-- [BEGIN] === Macro section === -->
    <!-- [BEGIN] ===  Macro section. ===-->
    <!-- [BEGIN] ===  Links section. ===-->
    <link name="base_link" />
    <link name="chassis_link">
        <inertial>
            <origin rpy="0 0 0" xyz="-0.25 0.0 -0.05" />
            <mass value="30" />
            <inertia ixx="0.584" ixy="0.0" ixz="0.0" iyy="1.189" iyz="0.0" izz="1.573" />
        </inertial>
        <!--Primitives with materials need to be used before .dae, otherwise material does not get applied-->
        <visual>
            <origin rpy="0 0 0" xyz="0.0 0.0 0.0" />
            <geometry>
                <mesh filename="package://sieglinde_new/meshes/chassis_tracker/tracker_chassis_no_tracks.dae" />
            </geometry>
        </visual>
        <visual>
            <origin rpy="0 0 0" xyz="-0.251 -0.265 -0.1" />
            <geometry>
                <mesh filename="package://sieglinde_new/meshes/chassis_tracker/tracker_chassis_sides.dae" />
            </geometry>
            <material name="black">
                <color rgba="0 0 0 1" />
            </material>
        </visual>
        <visual>
            <origin rpy="0 0 0" xyz="-0.251 0.265 -0.1" />
            <geometry>
                <mesh filename="package://sieglinde_new/meshes/chassis_tracker/tracker_chassis_sides.dae" />
            </geometry>
            <material name="black">
                <color rgba="0 0 0 1" />
            </material>
        </visual>
        <!--Left/right track box geoms-->
        <collision>
            <origin rpy="0 0 0" xyz="-0.251 -0.265 -0.1" />
            <geometry>
                <box size="0.438 0.0925 0.26" />
            </geometry>
        </collision>
        <collision>
            <origin rpy="0 0 0" xyz="-0.251  0.265 -0.1" />
            <geometry>
                <box size="0.438 0.0925 0.26" />
            </geometry>
        </collision>
        <!--Left/right back track cylinder geoms-->
        <collision>
            <origin rpy="1.5707963267948966 0 0" xyz="-0.47 -0.265 -0.1" />
            <geometry>
                <cylinder length="0.0925" radius="0.13" />
            </geometry>
            <material name="red">
                <color rgba="1 0 0 1" />
            </material>
        </collision>
        <collision>
            <origin rpy="1.5707963267948966 0 0" xyz="-0.47 0.265 -0.1" />
            <geometry>
                <cylinder length="0.0925" radius="0.13" />
            </geometry>
        </collision>
        <!--Chassis middle-->
        <collision>
            <origin rpy="0 0 0" xyz="-0.23 0.0 -0.075" />
            <geometry>
                <box size="0.7 0.5 0.15" />
            </geometry>
        </collision>
        <!-- Battery lid -->
        <collision>
            <origin rpy="0 0 0" xyz="-0.28 0.09 0.020000000000000004" />
            <geometry>
                <box size="0.25 0.15 0.10" />
            </geometry>
        </collision>
    </link>
    <link name="flipper_link_mimic">
        <inertial>
            <origin rpy="0 0 0" xyz="0.0 0.0 0.0" />
            <mass value="2.0" />
            <inertia ixx="0.010896796683333331" ixy="0.0" ixz="0.0" iyy="0.015609296683333333" iyz="0.0" izz="0.016120833333333334" />
        </inertial>
        <origin rpy="0 0 0" xyz="0 0 0" />
        <visual>
            <origin rpy="1.5707963267948966 0 0" xyz="0.69 -0.265 0.0" />
            <geometry>
                <cylinder length="0.0925" radius="0.13" />
            </geometry>
            <material name="black">
                <color rgba="0 0 0 1" />
            </material>
        </visual>
        <visual>
            <origin rpy="1.5707963267948966 0 0" xyz="0 -0.265 0.0" />
            <geometry>
                <cylinder length="0.0925" radius="0.13" />
            </geometry>
            <material name="black">
                <color rgba="0 0 0 1" />
            </material>
        </visual>
        <visual>
            <origin rpy="0 0 0" xyz="0.345 -0.265 0.0" />
            <geometry>
                <box size="0.69 0.0925 0.26" />
            </geometry>
            <material name="black">
                <color rgba="0 0 0 1" />
            </material>
        </visual>
        <visual>
            <origin rpy="1.5707963267948966 0 0" xyz="0.69 0.265 0.0" />
            <geometry>
                <cylinder length="0.0925" radius="0.13" />
            </geometry>
            <material name="black">
                <color rgba="0 0 0 1" />
            </material>
        </visual>
        <visual>
            <origin rpy="1.5707963267948966 0 0" xyz="0 0.265 0.0" />
            <geometry>
                <cylinder length="0.0925" radius="0.13" />
            </geometry>
            <material name="black">
                <color rgba="0 0 0 1" />
            </material>
        </visual>
        <visual>
            <origin rpy="0 0 0" xyz="0.345 0.265 0.0" />
            <geometry>
                <box size="0.69 0.0925 0.26" />
            </geometry>
            <material name="black">
                <color rgba="0 0 0 1" />
            </material>
        </visual>
        <collision>
            <origin rpy="1.5707963267948966 0 0" xyz="0.74 -0.265 0.0" />
            <geometry>
                <cylinder length="0.0925" radius="0.13" />
            </geometry>
        </collision>
        <collision>
            <origin rpy="1.5707963267948966 0 0" xyz="0 -0.265 0.0" />
            <geometry>
                <cylinder length="0.0925" radius="0.13" />
            </geometry>
        </collision>
        <collision>
            <origin rpy="0 0 0" xyz="0.37 -0.265 0.0" />
            <geometry>
                <box size="0.74 0.0925 0.26" />
            </geometry>
        </collision>
        <collision>
            <origin rpy="1.5707963267948966 0 0" xyz="0.74 0.265 0.0" />
            <geometry>
                <cylinder length="0.0925" radius="0.13" />
            </geometry>
        </collision>
        <collision>
            <origin rpy="1.5707963267948966 0 0" xyz="0 0.265 0.0" />
            <geometry>
                <cylinder length="0.0925" radius="0.13" />
            </geometry>
        </collision>
        <collision>
            <origin rpy="0 0 0" xyz="0.37 0.265 0.0" />
            <geometry>
                <box size="0.74 0.0925 0.26" />
            </geometry>
        </collision>
    </link>
    <link name="flipper_link">
        <inertial>
            <origin rpy="0 0 0" xyz="0.24 0.0 0.0" />
            <mass value="1.0" />
            <inertia ixx="0.005448398341666666" ixy="0.0" ixz="0.0" iyy="0.023429648341666665" iyz="0.0" izz="0.023685416666666667" />
        </inertial>
        <origin rpy="0 0 0" xyz="0 0 0" />
        <visual>
            <origin rpy="1.5707963267948966 0 0" xyz="0.302 -0.265 0.0" />
            <geometry>
                <cylinder length="0.0925" radius="0.13" />
            </geometry>
            <material name="black">
                <color rgba="0 0 0 1" />
            </material>
        </visual>
        <visual>
            <origin rpy="1.5707963267948966 0 0" xyz="0 -0.265 0.0" />
            <geometry>
                <cylinder length="0.0925" radius="0.13" />
            </geometry>
            <material name="black">
                <color rgba="0.1 0.1 0.1 1" />
            </material>
        </visual>
        <visual>
            <origin rpy="0 0 0" xyz="0.151 -0.265 0.0" />
            <geometry>
                <box size="0.302 0.0925 0.26" />
            </geometry>
            <material name="black">
                <color rgba="0 0 0 1" />
            </material>
        </visual>
        <visual>
            <origin rpy="1.5707963267948966 0 0" xyz="0.302 0.265 0.0" />
            <geometry>
                <cylinder length="0.0925" radius="0.13" />
            </geometry>
            <material name="black">
                <color rgba="0 0 0 1" />
            </material>
        </visual>
        <visual>
            <origin rpy="1.5707963267948966 0 0" xyz="0 0.265 0.0" />
            <geometry>
                <cylinder length="0.0925" radius="0.13" />
            </geometry>
            <material name="black">
                <color rgba="0 0 0 1" />
            </material>
        </visual>
        <visual>
            <origin rpy="0 0 0" xyz="0.151 0.265 0.0" />
            <geometry>
                <box size="0.302 0.0925 0.26" />
            </geometry>
            <material name="black">
                <color rgba="0 0 0 1" />
            </material>
        </visual>
        <collision>
            <origin rpy="1.5707963267948966 0 0" xyz="0.302 -0.265 0.0" />
            <geometry>
                <cylinder length="0.0925" radius="0.13" />
            </geometry>
        </collision>
        <collision>
            <origin rpy="1.5707963267948966 0 0" xyz="0 -0.265 0.0" />
            <geometry>
                <cylinder length="0.0925" radius="0.13" />
            </geometry>
        </collision>
        <collision>
            <origin rpy="0 0 0" xyz="0.151 -0.265 0.0" />
            <geometry>
                <box size="0.302 0.0925 0.26" />
            </geometry>
        </collision>
        <collision>
            <origin rpy="1.5707963267948966 0 0" xyz="0.302 0.265 0.0" />
            <geometry>
                <cylinder length="0.0925" radius="0.13" />
            </geometry>
        </collision>
        <collision>
            <origin rpy="1.5707963267948966 0 0" xyz="0 0.265 0.0" />
            <geometry>
                <cylinder length="0.0925" radius="0.13" />
            </geometry>
        </collision>
        <collision>
            <origin rpy="0 0 0" xyz="0.151 0.265 0.0" />
            <geometry>
                <box size="0.302 0.0925 0.26" />
            </geometry>
        </collision>
    </link>
    <!-- [BEGIN] ===  Joints section. ===-->
    <joint name="arm_flange_joint" type="fixed">
        <origin rpy="-1.5707963267948966 0 3.141592653589793" xyz="0.0 0.0 0.0" />
        <parent link="chassis_link" />
        <child link="base_arm" />
    </joint>
    <joint name="chassis_joint" type="fixed">
        <origin rpy="0 0 0" xyz="0.23 0 0.193" />
        <parent link="base_link" />
        <child link="chassis_link" />
    </joint>
    <joint name="flipper_joint_mimic" type="revolute">
        <origin rpy="0 0 0" xyz="-0.47 0 -0.1" />
        <axis xyz="0 -1 0" />
        <mimic joint="flipper_joint" multiplier="0.46" />
        <limit effort="100000" lower="-2.9670597283903604" upper="3.141592653589793" velocity="62.83185307179586" />
        <parent link="chassis_link" />
        <child link="flipper_link_mimic" />
    </joint>
    <joint name="flipper_joint" type="revolute">
        <origin rpy="0 0 0" xyz="-0.032 0 -0.1" />
        <axis xyz="0 -1 0" />
        <limit effort="10000" lower="-0.3" upper="0.75" velocity="0.5235987755982988" />
        <parent link="chassis_link" />
        <child link="flipper_link" />
    </joint>
    <!-- [BEGIN] ===  Transmission section. Needed for ros_control===-->
    <transmission name="flipper_joint_mimic_joint_transmssion">
        <type>transmission_interface/SimpleTransmission</type>
        <joint name="flipper_joint_mimic">
            <hardwareInterface>hardware_interface/PositionJointInterface</hardwareInterface>
        </joint>
        <actuator name="flipper_joint_mimic_motor">
            <hardwareInterface>hardware_interface/PositionJointInterface</hardwareInterface>
            <mechanicalReduction>1</mechanicalReduction>
        </actuator>
    </transmission>
    <transmission name="flipper_joint_joint_transmssion">
        <type>transmission_interface/SimpleTransmission</type>
        <joint name="flipper_joint">
            <hardwareInterface>hardware_interface/PositionJointInterface</hardwareInterface>
        </joint>
        <actuator name="flipper_joint_motor">
            <hardwareInterface>hardware_interface/PositionJointInterface</hardwareInterface>
            <mechanicalReduction>1</mechanicalReduction>
        </actuator>
    </transmission>
    <!-- FHTW -->
    <!-- LIDAR -->
    <link name="velodyne_base_link">
        <inertial>
            <mass value="0.83" />
            <origin xyz="0 0 0.03585" rpy="0 0 0" />
            <inertia ixx="0.000908059425" ixy="0" ixz="0" iyy="0.000908059425" iyz="0" izz="0.0011049624" />
        </inertial>
        <visual>
            <geometry>
                <mesh filename="package://velodyne_description/meshes/VLP16_base_1.dae" />
            </geometry>
        </visual>
        <visual>
            <geometry>
                <mesh filename="package://velodyne_description/meshes/VLP16_base_2.dae" />
            </geometry>
        </visual>
        <collision>
            <origin rpy="0 0 0" xyz="0 0 0.03585" />
            <geometry>
                <cylinder length="0.0717" radius="0.0516" />
            </geometry>
        </collision>
    </link>
    <link name="velodyne">
        <inertial>
            <mass value="0.01" />
            <origin xyz="0 0 0" />
            <inertia ixx="1e-7" ixy="0" ixz="0" iyy="1e-7" iyz="0" izz="1e-7" />
        </inertial>
        <visual>
            <origin xyz="0 0 -0.0377" />
            <geometry>
                <mesh filename="package://velodyne_description/meshes/VLP16_scan.dae" />
            </geometry>
        </visual>
    </link>
    <joint name="velodyne_base" type="fixed">
        <parent link="chassis_link" />
        <child link="velodyne_base_link" />
        <origin rpy="0 0 0.0" xyz="-0.655 0 0.2" />
    </joint>
    <joint name="velodyne" type="fixed">
        <origin rpy="0 0 0" xyz="0 0 0.0377" />
        <parent link="velodyne_base_link" />
        <child link="velodyne" />
    </joint>
    <!-- IMU -->
    <link name="imu">
        <visual>
            <origin rpy="0 0 0" xyz="0 0 0" />
            <geometry>
                <cylinder length="0.02" radius="0.0525" />
            </geometry>
            <material name="Blue">
                <color rgba="0.1 0.1 0.9 1.0" />
            </material>
        </visual>
        <collision>
            <origin rpy="0 0 0" xyz="0 0 0" />
            <geometry>
                <cylinder length="0.02" radius="0.0525" />
            </geometry>
        </collision>
        <inertial>
            <mass value="0.1" />
            <origin xyz="0 0 0" rpy="0 0 0" />
            <inertia ixx="0.03" iyy="0.03" izz="0.03" ixy="0.0" ixz="0.0" iyz="0.0" />
        </inertial>
    </link>
    <joint name="imu" type="fixed">
        <origin rpy="0 0 0" xyz="0 0 0.04" />
        <parent link="velodyne" />
        <child link="imu" />
    </joint>
    <gazebo>
        <plugin filename="libgazebo_ros_control.so" name="gazebo_ros_control">
            <robotNamespace>/</robotNamespace>
        </plugin>
    </gazebo>
    <!-- [END] ===  Added ROS control plugins for gazebo simulation===-->
</robot>

